// Simple exception handling test
print("Before try block");

try {
    print("Inside try block");
    var x = 5;
    print(x);
} catch (error) {
    print("In catch block");
}

print("After try-catch");
